[2025-10-26T09:22:13.288+0000] {processor.py:186} INFO - Started process (PID=125) to work on /opt/airflow/dags/fraud_detection_training_dag.py
[2025-10-26T09:22:13.337+0000] {processor.py:914} INFO - Processing file /opt/airflow/dags/fraud_detection_training_dag.py for tasks to queue
[2025-10-26T09:22:13.393+0000] {logging_mixin.py:190} INFO - [2025-10-26T09:22:13.392+0000] {dagbag.py:588} INFO - Filling up the DagBag from /opt/airflow/dags/fraud_detection_training_dag.py
[2025-10-26T09:22:14.729+0000] {processor.py:925} INFO - DAG(s) 'fraud_detection_training' retrieved from /opt/airflow/dags/fraud_detection_training_dag.py
[2025-10-26T09:22:17.323+0000] {logging_mixin.py:190} INFO - [2025-10-26T09:22:17.312+0000] {dag.py:3239} INFO - Sync 1 DAGs
[2025-10-26T09:22:19.047+0000] {logging_mixin.py:190} INFO - [2025-10-26T09:22:19.046+0000] {dag.py:4180} INFO - Setting next_dagrun for fraud_detection_training to 2025-10-25 03:00:00+00:00, run_after=2025-10-26 03:00:00+00:00
[2025-10-26T09:22:20.638+0000] {processor.py:208} INFO - Processing /opt/airflow/dags/fraud_detection_training_dag.py took 7.733 seconds
[2025-10-26T09:22:52.060+0000] {processor.py:186} INFO - Started process (PID=134) to work on /opt/airflow/dags/fraud_detection_training_dag.py
[2025-10-26T09:22:52.078+0000] {processor.py:914} INFO - Processing file /opt/airflow/dags/fraud_detection_training_dag.py for tasks to queue
[2025-10-26T09:22:52.194+0000] {logging_mixin.py:190} INFO - [2025-10-26T09:22:52.175+0000] {dagbag.py:588} INFO - Filling up the DagBag from /opt/airflow/dags/fraud_detection_training_dag.py
[2025-10-26T09:22:57.231+0000] {processor.py:925} INFO - DAG(s) 'fraud_detection_training' retrieved from /opt/airflow/dags/fraud_detection_training_dag.py
[2025-10-26T09:23:02.334+0000] {logging_mixin.py:190} INFO - [2025-10-26T09:23:02.333+0000] {dag.py:3239} INFO - Sync 1 DAGs
[2025-10-26T09:23:12.632+0000] {logging_mixin.py:190} INFO - [2025-10-26T09:23:12.632+0000] {dag.py:4180} INFO - Setting next_dagrun for fraud_detection_training to 2025-10-25 03:00:00+00:00, run_after=2025-10-26 03:00:00+00:00
[2025-10-26T09:23:15.660+0000] {processor.py:208} INFO - Processing /opt/airflow/dags/fraud_detection_training_dag.py took 20.935 seconds
[2025-10-26T09:23:48.304+0000] {processor.py:186} INFO - Started process (PID=142) to work on /opt/airflow/dags/fraud_detection_training_dag.py
[2025-10-26T09:23:48.443+0000] {processor.py:914} INFO - Processing file /opt/airflow/dags/fraud_detection_training_dag.py for tasks to queue
[2025-10-26T09:23:48.708+0000] {logging_mixin.py:190} INFO - [2025-10-26T09:23:48.668+0000] {dagbag.py:588} INFO - Filling up the DagBag from /opt/airflow/dags/fraud_detection_training_dag.py
[2025-10-26T09:24:03.152+0000] {logging_mixin.py:190} INFO - [2025-10-26T09:24:01.150+0000] {variable.py:357} ERROR - Unable to retrieve variable from secrets backend (MetastoreBackend). Checking subsequent secrets backend.
Traceback (most recent call last):
  File "/home/airflow/.local/lib/python3.12/site-packages/sqlalchemy/engine/base.py", line 3371, in _wrap_pool_connect
    return fn()
           ^^^^
  File "/home/airflow/.local/lib/python3.12/site-packages/sqlalchemy/pool/base.py", line 327, in connect
    return _ConnectionFairy._checkout(self)
           ^^^^^^^^^^^^^^^^^^^^^^^^^^^^^^^^
  File "/home/airflow/.local/lib/python3.12/site-packages/sqlalchemy/pool/base.py", line 894, in _checkout
    fairy = _ConnectionRecord.checkout(pool)
            ^^^^^^^^^^^^^^^^^^^^^^^^^^^^^^^^
  File "/home/airflow/.local/lib/python3.12/site-packages/sqlalchemy/pool/base.py", line 493, in checkout
    rec = pool._do_get()
          ^^^^^^^^^^^^^^
  File "/home/airflow/.local/lib/python3.12/site-packages/sqlalchemy/pool/impl.py", line 145, in _do_get
    with util.safe_reraise():
         ^^^^^^^^^^^^^^^^^^^
  File "/home/airflow/.local/lib/python3.12/site-packages/sqlalchemy/util/langhelpers.py", line 70, in __exit__
    compat.raise_(
  File "/home/airflow/.local/lib/python3.12/site-packages/sqlalchemy/util/compat.py", line 211, in raise_
    raise exception
  File "/home/airflow/.local/lib/python3.12/site-packages/sqlalchemy/pool/impl.py", line 143, in _do_get
    return self._create_connection()
           ^^^^^^^^^^^^^^^^^^^^^^^^^
  File "/home/airflow/.local/lib/python3.12/site-packages/sqlalchemy/pool/base.py", line 273, in _create_connection
    return _ConnectionRecord(self)
           ^^^^^^^^^^^^^^^^^^^^^^^
  File "/home/airflow/.local/lib/python3.12/site-packages/sqlalchemy/pool/base.py", line 388, in __init__
    self.__connect()
  File "/home/airflow/.local/lib/python3.12/site-packages/sqlalchemy/pool/base.py", line 690, in __connect
    with util.safe_reraise():
         ^^^^^^^^^^^^^^^^^^^
  File "/home/airflow/.local/lib/python3.12/site-packages/sqlalchemy/util/langhelpers.py", line 70, in __exit__
    compat.raise_(
  File "/home/airflow/.local/lib/python3.12/site-packages/sqlalchemy/util/compat.py", line 211, in raise_
    raise exception
  File "/home/airflow/.local/lib/python3.12/site-packages/sqlalchemy/pool/base.py", line 686, in __connect
    self.dbapi_connection = connection = pool._invoke_creator(self)
                                         ^^^^^^^^^^^^^^^^^^^^^^^^^^
  File "/home/airflow/.local/lib/python3.12/site-packages/sqlalchemy/engine/create.py", line 574, in connect
    return dialect.connect(*cargs, **cparams)
           ^^^^^^^^^^^^^^^^^^^^^^^^^^^^^^^^^^
  File "/home/airflow/.local/lib/python3.12/site-packages/sqlalchemy/engine/default.py", line 598, in connect
    return self.dbapi.connect(*cargs, **cparams)
           ^^^^^^^^^^^^^^^^^^^^^^^^^^^^^^^^^^^^^
  File "/home/airflow/.local/lib/python3.12/site-packages/psycopg2/__init__.py", line 122, in connect
    conn = _connect(dsn, connection_factory=connection_factory, **kwasync)
           ^^^^^^^^^^^^^^^^^^^^^^^^^^^^^^^^^^^^^^^^^^^^^^^^^^^^^^^^^^^^^^^
psycopg2.OperationalError: could not translate host name "postgres" to address: Temporary failure in name resolution


The above exception was the direct cause of the following exception:

Traceback (most recent call last):
  File "/home/airflow/.local/lib/python3.12/site-packages/airflow/models/variable.py", line 353, in get_variable_from_secrets
    var_val = secrets_backend.get_variable(key=key)
              ^^^^^^^^^^^^^^^^^^^^^^^^^^^^^^^^^^^^^
  File "/home/airflow/.local/lib/python3.12/site-packages/airflow/utils/session.py", line 97, in wrapper
    return func(*args, session=session, **kwargs)
           ^^^^^^^^^^^^^^^^^^^^^^^^^^^^^^^^^^^^^^
  File "/home/airflow/.local/lib/python3.12/site-packages/airflow/secrets/metastore.py", line 66, in get_variable
    return MetastoreBackend._fetch_variable(key=key, session=session)
           ^^^^^^^^^^^^^^^^^^^^^^^^^^^^^^^^^^^^^^^^^^^^^^^^^^^^^^^^^^
  File "/home/airflow/.local/lib/python3.12/site-packages/airflow/api_internal/internal_api_call.py", line 166, in wrapper
    return func(*args, **kwargs)
           ^^^^^^^^^^^^^^^^^^^^^
  File "/home/airflow/.local/lib/python3.12/site-packages/airflow/utils/session.py", line 94, in wrapper
    return func(*args, **kwargs)
           ^^^^^^^^^^^^^^^^^^^^^
  File "/home/airflow/.local/lib/python3.12/site-packages/airflow/secrets/metastore.py", line 84, in _fetch_variable
    var_value = session.scalar(select(Variable).where(Variable.key == key).limit(1))
                ^^^^^^^^^^^^^^^^^^^^^^^^^^^^^^^^^^^^^^^^^^^^^^^^^^^^^^^^^^^^^^^^^^^^
  File "/home/airflow/.local/lib/python3.12/site-packages/sqlalchemy/orm/session.py", line 1747, in scalar
    return self.execute(
           ^^^^^^^^^^^^^
  File "/home/airflow/.local/lib/python3.12/site-packages/sqlalchemy/orm/session.py", line 1716, in execute
    conn = self._connection_for_bind(bind)
           ^^^^^^^^^^^^^^^^^^^^^^^^^^^^^^^
  File "/home/airflow/.local/lib/python3.12/site-packages/sqlalchemy/orm/session.py", line 1555, in _connection_for_bind
    return self._transaction._connection_for_bind(
           ^^^^^^^^^^^^^^^^^^^^^^^^^^^^^^^^^^^^^^^
  File "/home/airflow/.local/lib/python3.12/site-packages/sqlalchemy/orm/session.py", line 750, in _connection_for_bind
    conn = bind.connect()
           ^^^^^^^^^^^^^^
  File "/home/airflow/.local/lib/python3.12/site-packages/sqlalchemy/future/engine.py", line 412, in connect
    return super(Engine, self).connect()
           ^^^^^^^^^^^^^^^^^^^^^^^^^^^^^
  File "/home/airflow/.local/lib/python3.12/site-packages/sqlalchemy/engine/base.py", line 3325, in connect
    return self._connection_cls(self, close_with_result=close_with_result)
           ^^^^^^^^^^^^^^^^^^^^^^^^^^^^^^^^^^^^^^^^^^^^^^^^^^^^^^^^^^^^^^^
  File "/home/airflow/.local/lib/python3.12/site-packages/sqlalchemy/engine/base.py", line 96, in __init__
    else engine.raw_connection()
         ^^^^^^^^^^^^^^^^^^^^^^^
  File "/home/airflow/.local/lib/python3.12/site-packages/sqlalchemy/engine/base.py", line 3404, in raw_connection
    return self._wrap_pool_connect(self.pool.connect, _connection)
           ^^^^^^^^^^^^^^^^^^^^^^^^^^^^^^^^^^^^^^^^^^^^^^^^^^^^^^^
  File "/home/airflow/.local/lib/python3.12/site-packages/sqlalchemy/engine/base.py", line 3374, in _wrap_pool_connect
    Connection._handle_dbapi_exception_noconnection(
  File "/home/airflow/.local/lib/python3.12/site-packages/sqlalchemy/engine/base.py", line 2208, in _handle_dbapi_exception_noconnection
    util.raise_(
  File "/home/airflow/.local/lib/python3.12/site-packages/sqlalchemy/util/compat.py", line 211, in raise_
    raise exception
  File "/home/airflow/.local/lib/python3.12/site-packages/sqlalchemy/engine/base.py", line 3371, in _wrap_pool_connect
    return fn()
           ^^^^
  File "/home/airflow/.local/lib/python3.12/site-packages/sqlalchemy/pool/base.py", line 327, in connect
    return _ConnectionFairy._checkout(self)
           ^^^^^^^^^^^^^^^^^^^^^^^^^^^^^^^^
  File "/home/airflow/.local/lib/python3.12/site-packages/sqlalchemy/pool/base.py", line 894, in _checkout
    fairy = _ConnectionRecord.checkout(pool)
            ^^^^^^^^^^^^^^^^^^^^^^^^^^^^^^^^
  File "/home/airflow/.local/lib/python3.12/site-packages/sqlalchemy/pool/base.py", line 493, in checkout
    rec = pool._do_get()
          ^^^^^^^^^^^^^^
  File "/home/airflow/.local/lib/python3.12/site-packages/sqlalchemy/pool/impl.py", line 145, in _do_get
    with util.safe_reraise():
         ^^^^^^^^^^^^^^^^^^^
  File "/home/airflow/.local/lib/python3.12/site-packages/sqlalchemy/util/langhelpers.py", line 70, in __exit__
    compat.raise_(
  File "/home/airflow/.local/lib/python3.12/site-packages/sqlalchemy/util/compat.py", line 211, in raise_
    raise exception
  File "/home/airflow/.local/lib/python3.12/site-packages/sqlalchemy/pool/impl.py", line 143, in _do_get
    return self._create_connection()
           ^^^^^^^^^^^^^^^^^^^^^^^^^
  File "/home/airflow/.local/lib/python3.12/site-packages/sqlalchemy/pool/base.py", line 273, in _create_connection
    return _ConnectionRecord(self)
           ^^^^^^^^^^^^^^^^^^^^^^^
  File "/home/airflow/.local/lib/python3.12/site-packages/sqlalchemy/pool/base.py", line 388, in __init__
    self.__connect()
  File "/home/airflow/.local/lib/python3.12/site-packages/sqlalchemy/pool/base.py", line 690, in __connect
    with util.safe_reraise():
         ^^^^^^^^^^^^^^^^^^^
  File "/home/airflow/.local/lib/python3.12/site-packages/sqlalchemy/util/langhelpers.py", line 70, in __exit__
    compat.raise_(
  File "/home/airflow/.local/lib/python3.12/site-packages/sqlalchemy/util/compat.py", line 211, in raise_
    raise exception
  File "/home/airflow/.local/lib/python3.12/site-packages/sqlalchemy/pool/base.py", line 686, in __connect
    self.dbapi_connection = connection = pool._invoke_creator(self)
                                         ^^^^^^^^^^^^^^^^^^^^^^^^^^
  File "/home/airflow/.local/lib/python3.12/site-packages/sqlalchemy/engine/create.py", line 574, in connect
    return dialect.connect(*cargs, **cparams)
           ^^^^^^^^^^^^^^^^^^^^^^^^^^^^^^^^^^
  File "/home/airflow/.local/lib/python3.12/site-packages/sqlalchemy/engine/default.py", line 598, in connect
    return self.dbapi.connect(*cargs, **cparams)
           ^^^^^^^^^^^^^^^^^^^^^^^^^^^^^^^^^^^^^
  File "/home/airflow/.local/lib/python3.12/site-packages/psycopg2/__init__.py", line 122, in connect
    conn = _connect(dsn, connection_factory=connection_factory, **kwasync)
           ^^^^^^^^^^^^^^^^^^^^^^^^^^^^^^^^^^^^^^^^^^^^^^^^^^^^^^^^^^^^^^^
sqlalchemy.exc.OperationalError: (psycopg2.OperationalError) could not translate host name "postgres" to address: Temporary failure in name resolution

(Background on this error at: https://sqlalche.me/e/14/e3q8)
[2025-10-26T09:24:04.926+0000] {processor.py:925} INFO - DAG(s) 'fraud_detection_training' retrieved from /opt/airflow/dags/fraud_detection_training_dag.py
[2025-10-26T09:25:09.286+0000] {processor.py:186} INFO - Started process (PID=145) to work on /opt/airflow/dags/fraud_detection_training_dag.py
[2025-10-26T09:25:09.362+0000] {processor.py:914} INFO - Processing file /opt/airflow/dags/fraud_detection_training_dag.py for tasks to queue
[2025-10-26T09:25:09.537+0000] {logging_mixin.py:190} INFO - [2025-10-26T09:25:09.536+0000] {dagbag.py:588} INFO - Filling up the DagBag from /opt/airflow/dags/fraud_detection_training_dag.py
[2025-10-26T09:25:15.927+0000] {processor.py:925} INFO - DAG(s) 'fraud_detection_training' retrieved from /opt/airflow/dags/fraud_detection_training_dag.py
[2025-10-26T09:25:20.151+0000] {logging_mixin.py:190} INFO - [2025-10-26T09:25:20.060+0000] {dag.py:3239} INFO - Sync 1 DAGs
[2025-10-26T09:25:24.408+0000] {logging_mixin.py:190} INFO - [2025-10-26T09:25:24.384+0000] {dag.py:4180} INFO - Setting next_dagrun for fraud_detection_training to 2025-10-25 03:00:00+00:00, run_after=2025-10-26 03:00:00+00:00
[2025-10-26T09:25:25.600+0000] {processor.py:208} INFO - Processing /opt/airflow/dags/fraud_detection_training_dag.py took 16.718 seconds
[2025-10-26T09:31:26.908+0000] {processor.py:186} INFO - Started process (PID=147) to work on /opt/airflow/dags/fraud_detection_training_dag.py
[2025-10-26T09:31:27.128+0000] {processor.py:914} INFO - Processing file /opt/airflow/dags/fraud_detection_training_dag.py for tasks to queue
[2025-10-26T09:31:28.861+0000] {logging_mixin.py:190} INFO - [2025-10-26T09:31:28.575+0000] {dagbag.py:588} INFO - Filling up the DagBag from /opt/airflow/dags/fraud_detection_training_dag.py
[2025-10-26T09:32:30.621+0000] {logging_mixin.py:190} INFO - [2025-10-26T09:32:07.151+0000] {timeout.py:68} ERROR - Process timed out, PID: 147
[2025-10-26T12:53:50.107+0000] {processor.py:186} INFO - Started process (PID=97) to work on /opt/airflow/dags/fraud_detection_training_dag.py
[2025-10-26T12:53:50.134+0000] {processor.py:914} INFO - Processing file /opt/airflow/dags/fraud_detection_training_dag.py for tasks to queue
[2025-10-26T12:53:50.213+0000] {logging_mixin.py:190} INFO - [2025-10-26T12:53:50.208+0000] {dagbag.py:588} INFO - Filling up the DagBag from /opt/airflow/dags/fraud_detection_training_dag.py
[2025-10-26T12:53:51.011+0000] {processor.py:925} INFO - DAG(s) 'fraud_detection_training' retrieved from /opt/airflow/dags/fraud_detection_training_dag.py
[2025-10-26T12:53:51.280+0000] {logging_mixin.py:190} INFO - [2025-10-26T12:53:51.279+0000] {dag.py:3239} INFO - Sync 1 DAGs
[2025-10-26T12:53:51.781+0000] {logging_mixin.py:190} INFO - [2025-10-26T12:53:51.780+0000] {dag.py:4180} INFO - Setting next_dagrun for fraud_detection_training to 2025-10-25 03:00:00+00:00, run_after=2025-10-26 03:00:00+00:00
[2025-10-26T12:53:51.962+0000] {processor.py:208} INFO - Processing /opt/airflow/dags/fraud_detection_training_dag.py took 2.024 seconds
[2025-10-26T12:54:23.160+0000] {processor.py:186} INFO - Started process (PID=106) to work on /opt/airflow/dags/fraud_detection_training_dag.py
[2025-10-26T12:54:23.170+0000] {processor.py:914} INFO - Processing file /opt/airflow/dags/fraud_detection_training_dag.py for tasks to queue
[2025-10-26T12:54:23.285+0000] {logging_mixin.py:190} INFO - [2025-10-26T12:54:23.258+0000] {dagbag.py:588} INFO - Filling up the DagBag from /opt/airflow/dags/fraud_detection_training_dag.py
[2025-10-26T12:54:24.572+0000] {processor.py:925} INFO - DAG(s) 'fraud_detection_training' retrieved from /opt/airflow/dags/fraud_detection_training_dag.py
[2025-10-26T12:54:25.125+0000] {logging_mixin.py:190} INFO - [2025-10-26T12:54:25.124+0000] {dag.py:3239} INFO - Sync 1 DAGs
[2025-10-26T12:54:26.264+0000] {logging_mixin.py:190} INFO - [2025-10-26T12:54:26.260+0000] {dag.py:4180} INFO - Setting next_dagrun for fraud_detection_training to 2025-10-25 03:00:00+00:00, run_after=2025-10-26 03:00:00+00:00
[2025-10-26T12:54:27.164+0000] {processor.py:208} INFO - Processing /opt/airflow/dags/fraud_detection_training_dag.py took 4.295 seconds
[2025-10-26T12:54:57.899+0000] {processor.py:186} INFO - Started process (PID=114) to work on /opt/airflow/dags/fraud_detection_training_dag.py
[2025-10-26T12:54:57.904+0000] {processor.py:914} INFO - Processing file /opt/airflow/dags/fraud_detection_training_dag.py for tasks to queue
[2025-10-26T12:54:57.928+0000] {logging_mixin.py:190} INFO - [2025-10-26T12:54:57.924+0000] {dagbag.py:588} INFO - Filling up the DagBag from /opt/airflow/dags/fraud_detection_training_dag.py
[2025-10-26T12:54:58.730+0000] {processor.py:925} INFO - DAG(s) 'fraud_detection_training' retrieved from /opt/airflow/dags/fraud_detection_training_dag.py
[2025-10-26T12:54:59.359+0000] {logging_mixin.py:190} INFO - [2025-10-26T12:54:59.358+0000] {dag.py:3239} INFO - Sync 1 DAGs
[2025-10-26T12:54:59.906+0000] {logging_mixin.py:190} INFO - [2025-10-26T12:54:59.905+0000] {dag.py:4180} INFO - Setting next_dagrun for fraud_detection_training to 2025-10-25 03:00:00+00:00, run_after=2025-10-26 03:00:00+00:00
[2025-10-26T12:55:00.238+0000] {processor.py:208} INFO - Processing /opt/airflow/dags/fraud_detection_training_dag.py took 2.416 seconds
[2025-10-26T12:55:31.361+0000] {processor.py:186} INFO - Started process (PID=128) to work on /opt/airflow/dags/fraud_detection_training_dag.py
[2025-10-26T12:55:31.378+0000] {processor.py:914} INFO - Processing file /opt/airflow/dags/fraud_detection_training_dag.py for tasks to queue
[2025-10-26T12:55:31.435+0000] {logging_mixin.py:190} INFO - [2025-10-26T12:55:31.429+0000] {dagbag.py:588} INFO - Filling up the DagBag from /opt/airflow/dags/fraud_detection_training_dag.py
[2025-10-26T12:55:33.101+0000] {processor.py:925} INFO - DAG(s) 'fraud_detection_training' retrieved from /opt/airflow/dags/fraud_detection_training_dag.py
[2025-10-26T12:55:34.217+0000] {logging_mixin.py:190} INFO - [2025-10-26T12:55:34.216+0000] {dag.py:3239} INFO - Sync 1 DAGs
[2025-10-26T12:55:35.527+0000] {logging_mixin.py:190} INFO - [2025-10-26T12:55:35.522+0000] {dag.py:4180} INFO - Setting next_dagrun for fraud_detection_training to 2025-10-25 03:00:00+00:00, run_after=2025-10-26 03:00:00+00:00
[2025-10-26T12:55:36.119+0000] {processor.py:208} INFO - Processing /opt/airflow/dags/fraud_detection_training_dag.py took 4.953 seconds
[2025-10-26T12:56:06.552+0000] {processor.py:186} INFO - Started process (PID=136) to work on /opt/airflow/dags/fraud_detection_training_dag.py
[2025-10-26T12:56:06.558+0000] {processor.py:914} INFO - Processing file /opt/airflow/dags/fraud_detection_training_dag.py for tasks to queue
[2025-10-26T12:56:06.575+0000] {logging_mixin.py:190} INFO - [2025-10-26T12:56:06.574+0000] {dagbag.py:588} INFO - Filling up the DagBag from /opt/airflow/dags/fraud_detection_training_dag.py
[2025-10-26T12:56:06.824+0000] {processor.py:925} INFO - DAG(s) 'fraud_detection_training' retrieved from /opt/airflow/dags/fraud_detection_training_dag.py
[2025-10-26T12:56:07.034+0000] {logging_mixin.py:190} INFO - [2025-10-26T12:56:07.033+0000] {dag.py:3239} INFO - Sync 1 DAGs
[2025-10-26T12:56:07.218+0000] {logging_mixin.py:190} INFO - [2025-10-26T12:56:07.217+0000] {dag.py:4180} INFO - Setting next_dagrun for fraud_detection_training to 2025-10-25 03:00:00+00:00, run_after=2025-10-26 03:00:00+00:00
[2025-10-26T12:56:07.370+0000] {processor.py:208} INFO - Processing /opt/airflow/dags/fraud_detection_training_dag.py took 0.860 seconds
[2025-10-26T12:56:38.095+0000] {processor.py:186} INFO - Started process (PID=143) to work on /opt/airflow/dags/fraud_detection_training_dag.py
[2025-10-26T12:56:38.109+0000] {processor.py:914} INFO - Processing file /opt/airflow/dags/fraud_detection_training_dag.py for tasks to queue
[2025-10-26T12:56:38.123+0000] {logging_mixin.py:190} INFO - [2025-10-26T12:56:38.122+0000] {dagbag.py:588} INFO - Filling up the DagBag from /opt/airflow/dags/fraud_detection_training_dag.py
[2025-10-26T12:56:38.277+0000] {processor.py:925} INFO - DAG(s) 'fraud_detection_training' retrieved from /opt/airflow/dags/fraud_detection_training_dag.py
[2025-10-26T12:56:38.478+0000] {logging_mixin.py:190} INFO - [2025-10-26T12:56:38.478+0000] {dag.py:3239} INFO - Sync 1 DAGs
[2025-10-26T12:56:38.682+0000] {logging_mixin.py:190} INFO - [2025-10-26T12:56:38.681+0000] {dag.py:4180} INFO - Setting next_dagrun for fraud_detection_training to 2025-10-25 03:00:00+00:00, run_after=2025-10-26 03:00:00+00:00
[2025-10-26T12:56:38.819+0000] {processor.py:208} INFO - Processing /opt/airflow/dags/fraud_detection_training_dag.py took 0.775 seconds
[2025-10-26T12:57:13.470+0000] {processor.py:186} INFO - Started process (PID=145) to work on /opt/airflow/dags/fraud_detection_training_dag.py
[2025-10-26T12:57:13.684+0000] {processor.py:914} INFO - Processing file /opt/airflow/dags/fraud_detection_training_dag.py for tasks to queue
[2025-10-26T12:57:14.849+0000] {logging_mixin.py:190} INFO - [2025-10-26T12:57:14.546+0000] {dagbag.py:588} INFO - Filling up the DagBag from /opt/airflow/dags/fraud_detection_training_dag.py
[2025-10-26T12:58:33.621+0000] {logging_mixin.py:190} INFO - [2025-10-26T12:57:49.268+0000] {timeout.py:68} ERROR - Process timed out, PID: 145
[2025-10-26T13:05:43.923+0000] {logging_mixin.py:190} INFO - [2025-10-26T12:59:36.560+0000] {dagbag.py:387} ERROR - Failed to import: /opt/airflow/dags/fraud_detection_training_dag.py
Traceback (most recent call last):
  File "/home/airflow/.local/lib/python3.12/site-packages/cron_descriptor/GetText.py", line 48, in __init__
    self.trans = self.load_locale(locale_code, locale_location)
                 ^^^^^^^^^^^^^^^^^^^^^^^^^^^^^^^^^^^^^^^^^^^^^^
  File "/home/airflow/.local/lib/python3.12/site-packages/cron_descriptor/GetText.py", line 63, in load_locale
    with open(filename, "rb") as f:
         ^^^^^^^^^^^^^^^^^^^^
FileNotFoundError: [Errno 2] No such file or directory: '/home/airflow/.local/lib/python3.12/site-packages/cron_descriptor/locale/C.mo'

During handling of the above exception, another exception occurred:

Traceback (most recent call last):
  File "/home/airflow/.local/lib/python3.12/site-packages/airflow/models/dagbag.py", line 383, in parse
    loader.exec_module(new_module)
  File "<frozen importlib._bootstrap_external>", line 999, in exec_module
  File "<frozen importlib._bootstrap>", line 488, in _call_with_frames_removed
  File "/opt/airflow/dags/fraud_detection_training_dag.py", line 100, in <module>
    with DAG(
         ^^^^
  File "/home/airflow/.local/lib/python3.12/site-packages/airflow/models/dag.py", line 698, in __init__
    self.timetable = create_timetable(schedule, self.timezone)
                     ^^^^^^^^^^^^^^^^^^^^^^^^^^^^^^^^^^^^^^^^^
  File "/home/airflow/.local/lib/python3.12/site-packages/airflow/models/dag.py", line 246, in create_timetable
    return CronDataIntervalTimetable(interval, timezone)
           ^^^^^^^^^^^^^^^^^^^^^^^^^^^^^^^^^^^^^^^^^^^^^
  File "/home/airflow/.local/lib/python3.12/site-packages/airflow/timetables/_cron.py", line 74, in __init__
    descriptor = ExpressionDescriptor(
                 ^^^^^^^^^^^^^^^^^^^^^
  File "/home/airflow/.local/lib/python3.12/site-packages/cron_descriptor/ExpressionDescriptor.py", line 72, in __init__
    self.get_text = GetText(options.locale_code, options.locale_location)
                    ^^^^^^^^^^^^^^^^^^^^^^^^^^^^^^^^^^^^^^^^^^^^^^^^^^^^^
  File "/home/airflow/.local/lib/python3.12/site-packages/cron_descriptor/GetText.py", line 52, in __init__
    self.trans = self.load_locale('en_US')
                 ^^^^^^^^^^^^^^^^^^^^^^^^^
  File "/home/airflow/.local/lib/python3.12/site-packages/cron_descriptor/GetText.py", line 64, in load_locale
    trans = gettext.GNUTranslations(f)
            ^^^^^^^^^^^^^^^^^^^^^^^^^^
  File "/usr/local/lib/python3.12/gettext.py", line 272, in __init__
    self._parse(fp)
  File "/usr/local/lib/python3.12/gettext.py", line 370, in _parse
    for i in range(0, msgcount):
             ^^^^^^^^^^^^^^^^^^
  File "/home/airflow/.local/lib/python3.12/site-packages/airflow/utils/timeout.py", line 69, in handle_timeout
    raise AirflowTaskTimeout(self.error_message)
airflow.exceptions.AirflowTaskTimeout: DagBag import timeout for /opt/airflow/dags/fraud_detection_training_dag.py after 30.0s.
Please take a look at these docs to improve your DAG import time:
* https://airflow.apache.org/docs/apache-airflow/2.10.5/best-practices.html#top-level-python-code
* https://airflow.apache.org/docs/apache-airflow/2.10.5/best-practices.html#reducing-dag-complexity, PID: 145
[2025-10-26T13:06:47.141+0000] {processor.py:927} WARNING - No viable dags retrieved from /opt/airflow/dags/fraud_detection_training_dag.py
[2025-10-26T13:07:53.738+0000] {processor.py:211} ERROR - Got an exception! Propagating...
Traceback (most recent call last):
  File "/home/airflow/.local/lib/python3.12/site-packages/sqlalchemy/engine/base.py", line 3371, in _wrap_pool_connect
    return fn()
           ^^^^
  File "/home/airflow/.local/lib/python3.12/site-packages/sqlalchemy/pool/base.py", line 327, in connect
    return _ConnectionFairy._checkout(self)
           ^^^^^^^^^^^^^^^^^^^^^^^^^^^^^^^^
  File "/home/airflow/.local/lib/python3.12/site-packages/sqlalchemy/pool/base.py", line 894, in _checkout
    fairy = _ConnectionRecord.checkout(pool)
            ^^^^^^^^^^^^^^^^^^^^^^^^^^^^^^^^
  File "/home/airflow/.local/lib/python3.12/site-packages/sqlalchemy/pool/base.py", line 493, in checkout
    rec = pool._do_get()
          ^^^^^^^^^^^^^^
  File "/home/airflow/.local/lib/python3.12/site-packages/sqlalchemy/pool/impl.py", line 145, in _do_get
    with util.safe_reraise():
         ^^^^^^^^^^^^^^^^^^^
  File "/home/airflow/.local/lib/python3.12/site-packages/sqlalchemy/util/langhelpers.py", line 70, in __exit__
    compat.raise_(
  File "/home/airflow/.local/lib/python3.12/site-packages/sqlalchemy/util/compat.py", line 211, in raise_
    raise exception
  File "/home/airflow/.local/lib/python3.12/site-packages/sqlalchemy/pool/impl.py", line 143, in _do_get
    return self._create_connection()
           ^^^^^^^^^^^^^^^^^^^^^^^^^
  File "/home/airflow/.local/lib/python3.12/site-packages/sqlalchemy/pool/base.py", line 273, in _create_connection
    return _ConnectionRecord(self)
           ^^^^^^^^^^^^^^^^^^^^^^^
  File "/home/airflow/.local/lib/python3.12/site-packages/sqlalchemy/pool/base.py", line 388, in __init__
    self.__connect()
  File "/home/airflow/.local/lib/python3.12/site-packages/sqlalchemy/pool/base.py", line 690, in __connect
    with util.safe_reraise():
         ^^^^^^^^^^^^^^^^^^^
  File "/home/airflow/.local/lib/python3.12/site-packages/sqlalchemy/util/langhelpers.py", line 70, in __exit__
    compat.raise_(
  File "/home/airflow/.local/lib/python3.12/site-packages/sqlalchemy/util/compat.py", line 211, in raise_
    raise exception
  File "/home/airflow/.local/lib/python3.12/site-packages/sqlalchemy/pool/base.py", line 686, in __connect
    self.dbapi_connection = connection = pool._invoke_creator(self)
                                         ^^^^^^^^^^^^^^^^^^^^^^^^^^
  File "/home/airflow/.local/lib/python3.12/site-packages/sqlalchemy/engine/create.py", line 574, in connect
    return dialect.connect(*cargs, **cparams)
           ^^^^^^^^^^^^^^^^^^^^^^^^^^^^^^^^^^
  File "/home/airflow/.local/lib/python3.12/site-packages/sqlalchemy/engine/default.py", line 598, in connect
    return self.dbapi.connect(*cargs, **cparams)
           ^^^^^^^^^^^^^^^^^^^^^^^^^^^^^^^^^^^^^
  File "/home/airflow/.local/lib/python3.12/site-packages/psycopg2/__init__.py", line 122, in connect
    conn = _connect(dsn, connection_factory=connection_factory, **kwasync)
           ^^^^^^^^^^^^^^^^^^^^^^^^^^^^^^^^^^^^^^^^^^^^^^^^^^^^^^^^^^^^^^^
psycopg2.OperationalError: could not translate host name "postgres" to address: Temporary failure in name resolution


The above exception was the direct cause of the following exception:

Traceback (most recent call last):
  File "/home/airflow/.local/lib/python3.12/site-packages/airflow/dag_processing/processor.py", line 207, in _run_file_processor
    _handle_dag_file_processing()
  File "/home/airflow/.local/lib/python3.12/site-packages/airflow/dag_processing/processor.py", line 188, in _handle_dag_file_processing
    result: tuple[int, int, int] = dag_file_processor.process_file(
                                   ^^^^^^^^^^^^^^^^^^^^^^^^^^^^^^^^
  File "/home/airflow/.local/lib/python3.12/site-packages/airflow/utils/session.py", line 97, in wrapper
    return func(*args, session=session, **kwargs)
           ^^^^^^^^^^^^^^^^^^^^^^^^^^^^^^^^^^^^^^
  File "/home/airflow/.local/lib/python3.12/site-packages/airflow/dag_processing/processor.py", line 928, in process_file
    DagFileProcessor.update_import_errors(
  File "/home/airflow/.local/lib/python3.12/site-packages/airflow/api_internal/internal_api_call.py", line 166, in wrapper
    return func(*args, **kwargs)
           ^^^^^^^^^^^^^^^^^^^^^
  File "/home/airflow/.local/lib/python3.12/site-packages/airflow/utils/session.py", line 97, in wrapper
    return func(*args, session=session, **kwargs)
           ^^^^^^^^^^^^^^^^^^^^^^^^^^^^^^^^^^^^^^
  File "/home/airflow/.local/lib/python3.12/site-packages/airflow/dag_processing/processor.py", line 648, in update_import_errors
    existing_import_error_files = [x.filename for x in session.query(ParseImportError.filename).all()]
                                                       ^^^^^^^^^^^^^^^^^^^^^^^^^^^^^^^^^^^^^^^^^^^^^^
  File "/home/airflow/.local/lib/python3.12/site-packages/sqlalchemy/orm/query.py", line 2773, in all
    return self._iter().all()
           ^^^^^^^^^^^^
  File "/home/airflow/.local/lib/python3.12/site-packages/sqlalchemy/orm/query.py", line 2916, in _iter
    result = self.session.execute(
             ^^^^^^^^^^^^^^^^^^^^^
  File "/home/airflow/.local/lib/python3.12/site-packages/sqlalchemy/orm/session.py", line 1716, in execute
    conn = self._connection_for_bind(bind)
           ^^^^^^^^^^^^^^^^^^^^^^^^^^^^^^^
  File "/home/airflow/.local/lib/python3.12/site-packages/sqlalchemy/orm/session.py", line 1555, in _connection_for_bind
    return self._transaction._connection_for_bind(
           ^^^^^^^^^^^^^^^^^^^^^^^^^^^^^^^^^^^^^^^
  File "/home/airflow/.local/lib/python3.12/site-packages/sqlalchemy/orm/session.py", line 750, in _connection_for_bind
    conn = bind.connect()
           ^^^^^^^^^^^^^^
  File "/home/airflow/.local/lib/python3.12/site-packages/sqlalchemy/future/engine.py", line 412, in connect
    return super(Engine, self).connect()
           ^^^^^^^^^^^^^^^^^^^^^^^^^^^^^
  File "/home/airflow/.local/lib/python3.12/site-packages/sqlalchemy/engine/base.py", line 3325, in connect
    return self._connection_cls(self, close_with_result=close_with_result)
           ^^^^^^^^^^^^^^^^^^^^^^^^^^^^^^^^^^^^^^^^^^^^^^^^^^^^^^^^^^^^^^^
  File "/home/airflow/.local/lib/python3.12/site-packages/sqlalchemy/engine/base.py", line 96, in __init__
    else engine.raw_connection()
         ^^^^^^^^^^^^^^^^^^^^^^^
  File "/home/airflow/.local/lib/python3.12/site-packages/sqlalchemy/engine/base.py", line 3404, in raw_connection
    return self._wrap_pool_connect(self.pool.connect, _connection)
           ^^^^^^^^^^^^^^^^^^^^^^^^^^^^^^^^^^^^^^^^^^^^^^^^^^^^^^^
  File "/home/airflow/.local/lib/python3.12/site-packages/sqlalchemy/engine/base.py", line 3374, in _wrap_pool_connect
    Connection._handle_dbapi_exception_noconnection(
  File "/home/airflow/.local/lib/python3.12/site-packages/sqlalchemy/engine/base.py", line 2208, in _handle_dbapi_exception_noconnection
    util.raise_(
  File "/home/airflow/.local/lib/python3.12/site-packages/sqlalchemy/util/compat.py", line 211, in raise_
    raise exception
  File "/home/airflow/.local/lib/python3.12/site-packages/sqlalchemy/engine/base.py", line 3371, in _wrap_pool_connect
    return fn()
           ^^^^
  File "/home/airflow/.local/lib/python3.12/site-packages/sqlalchemy/pool/base.py", line 327, in connect
    return _ConnectionFairy._checkout(self)
           ^^^^^^^^^^^^^^^^^^^^^^^^^^^^^^^^
  File "/home/airflow/.local/lib/python3.12/site-packages/sqlalchemy/pool/base.py", line 894, in _checkout
    fairy = _ConnectionRecord.checkout(pool)
            ^^^^^^^^^^^^^^^^^^^^^^^^^^^^^^^^
  File "/home/airflow/.local/lib/python3.12/site-packages/sqlalchemy/pool/base.py", line 493, in checkout
    rec = pool._do_get()
          ^^^^^^^^^^^^^^
  File "/home/airflow/.local/lib/python3.12/site-packages/sqlalchemy/pool/impl.py", line 145, in _do_get
    with util.safe_reraise():
         ^^^^^^^^^^^^^^^^^^^
  File "/home/airflow/.local/lib/python3.12/site-packages/sqlalchemy/util/langhelpers.py", line 70, in __exit__
    compat.raise_(
  File "/home/airflow/.local/lib/python3.12/site-packages/sqlalchemy/util/compat.py", line 211, in raise_
    raise exception
  File "/home/airflow/.local/lib/python3.12/site-packages/sqlalchemy/pool/impl.py", line 143, in _do_get
    return self._create_connection()
           ^^^^^^^^^^^^^^^^^^^^^^^^^
  File "/home/airflow/.local/lib/python3.12/site-packages/sqlalchemy/pool/base.py", line 273, in _create_connection
    return _ConnectionRecord(self)
           ^^^^^^^^^^^^^^^^^^^^^^^
  File "/home/airflow/.local/lib/python3.12/site-packages/sqlalchemy/pool/base.py", line 388, in __init__
    self.__connect()
  File "/home/airflow/.local/lib/python3.12/site-packages/sqlalchemy/pool/base.py", line 690, in __connect
    with util.safe_reraise():
         ^^^^^^^^^^^^^^^^^^^
  File "/home/airflow/.local/lib/python3.12/site-packages/sqlalchemy/util/langhelpers.py", line 70, in __exit__
    compat.raise_(
  File "/home/airflow/.local/lib/python3.12/site-packages/sqlalchemy/util/compat.py", line 211, in raise_
    raise exception
  File "/home/airflow/.local/lib/python3.12/site-packages/sqlalchemy/pool/base.py", line 686, in __connect
    self.dbapi_connection = connection = pool._invoke_creator(self)
                                         ^^^^^^^^^^^^^^^^^^^^^^^^^^
  File "/home/airflow/.local/lib/python3.12/site-packages/sqlalchemy/engine/create.py", line 574, in connect
    return dialect.connect(*cargs, **cparams)
           ^^^^^^^^^^^^^^^^^^^^^^^^^^^^^^^^^^
  File "/home/airflow/.local/lib/python3.12/site-packages/sqlalchemy/engine/default.py", line 598, in connect
    return self.dbapi.connect(*cargs, **cparams)
           ^^^^^^^^^^^^^^^^^^^^^^^^^^^^^^^^^^^^^
  File "/home/airflow/.local/lib/python3.12/site-packages/psycopg2/__init__.py", line 122, in connect
    conn = _connect(dsn, connection_factory=connection_factory, **kwasync)
           ^^^^^^^^^^^^^^^^^^^^^^^^^^^^^^^^^^^^^^^^^^^^^^^^^^^^^^^^^^^^^^^
sqlalchemy.exc.OperationalError: (psycopg2.OperationalError) could not translate host name "postgres" to address: Temporary failure in name resolution

(Background on this error at: https://sqlalche.me/e/14/e3q8)
